Workbook
Name BalCheck: Model!$G$115
Name Circularity: Cover!$C$14
Name Million: Assumptions!$F$9
Name S_List: Scenario!$D$12:$D$14
Name S_Scenario: Scenario!$F$9

Sheet Cover
B4: =Historical!B2 -> Xcel Stores & Properties
B6: ="Financial Forecast from "&Historical!I7+1&" to "&Historical!I7+5 -> Financial Forecast from 2023 to 2027
B8: Version | C8: V1.01
B10: Modeller: | C10: Animashaun Jafar
B12: Circularity in the Model: | C12: Net Interest Expense
B14: Circularity Switch>>>>> | C14: 2
B17: =IF(Circularity=1,"Circularity is now turned on in the model, kindly follow the steps below to enable iterative calculation:","")
B19: =IF(Circularity=1,"Click on File>>Options>>Formulas>>Calculation Options>>Check Enable Iterative Calculation>>OK","")
B20: =IF(Circularity=1,"Alternatively, use the Excel Shortcut ALT + F + T to quickly navigate to Excel Options, then follow other steps as stated above","")
B22: © This Model is a copyright material of dbrownconsulting. It is solely for educational purpose and should not be used otherwise without prior written permission.

Sheet Historical
B2: Xcel Stores & Properties
B3: Income Statement
B5: Millions for the Year Ended December 31
G7: 2020 | H7: =G7+1 -> 2021 | I7: =H7+1 -> 2022
B9: Revenue Growth | H9: =H13/G13-1 -> 0.1050833 | I9: =I13/H13-1 -> 0.078082721
B10: COGS (% of revenue) | G10: =G15/G$13 -> 0.31866724 | H10: =H15/H$13 -> 0.35485118 | I10: =I15/I$13 -> 0.36894944
B11: SG&A (% of revenue) | G11: =G16/G$13 -> 0.061939342 | H11: =H16/H$13 -> 0.065326633 | I11: =I16/I$13 -> 0.070993188
C13: Revenue | G13: 234.1 | H13: 258.7 | I13: 278.9
C15: Operating Costs | G15: 74.6 | H15: 91.8 | I15: 102.9
C16: SG&A | G16: 14.5 | H16: 16.9 | I16: 19.8
C17: Total Costs | G17: =SUM(G15:G16) -> 89.1 | H17: =SUM(H15:H16) -> 108.7 | I17: =SUM(I15:I16) -> 122.7
C19: Cost Adjustments - Gain / (Loss) | G19: 0 | H19: 0.8 | I19: 2.3
C20: EBITDA | G20: =G13-G17+G19 -> 145 | H20: =H13-H17+H19 -> 150.8 | I20: =I13-I17+I19 -> 158.5
C22: Depreciation | G22: 41.7 | H22: 46.2 | I22: 54.6
C23: EBIT | G23: =G20-G22 -> 103.3 | H23: =H20-H22 -> 104.6 | I23: =I20-I22 -> 103.9
C25: Foreign Exchange - Gain / (Loss) | G25: 0 | H25: -2.6 | I25: 0
C26: Net Interest Expense | G26: 33.5 | H26: 34.2 | I26: 36.6
C27: EBT | G27: =G23+G25-G26 -> 69.8 | H27: =H23+H25-H26 -> 67.8 | I27: =I23+I25-I26 -> 67.3
C29: Current Taxes | G29: 11.3 | H29: 10.5 | I29: 15.8
C30: Deferred Income Taxes | G30: 10.4 | H30: 11.8 | I30: 8.4
C31: Total Income Taxes | G31: =SUM(G29:G30) -> 21.7 | H31: =SUM(H29:H30) -> 22.3 | I31: =SUM(I29:I30) -> 24.2
C33: Net Income | G33: =G27-G31 -> 48.1 | H33: =H27-H31 -> 45.5 | I33: =I27-I31 -> 43.1
C35: Preferred Dividend | G35: 0 | H35: 0 | I35: 0
C36: Net Income to Common | G36: =G33-G35 -> 48.1 | H36: =H33-H35 -> 45.5 | I36: =I33-I35 -> 43.1
B41: =$B$2 -> Xcel Stores & Properties
B42: Cash Flow Statement
B44: =$B$5 -> Millions for the Year Ended December 31
G46: =G$7 -> 2020 | H46: =H$7 -> 2021 | I46: =I$7 -> 2022
B48: Operating Activities
C49: Net Income | G49: 48.1 | H49: 45.5 | I49: 43.1
C50: Depreciation | G50: 41.7 | H50: 46.2 | I50: 54.6
C51: Deferred Income Taxes | G51: 10.4 | H51: 11.8 | I51: 8.4
C52: Changes in Working Capital | G52: 2.4 | H52: 6.7 | I52: -3.3
C53: Other | G53: 0.4 | H53: -0.4 | I53: -0.3
C54: Operating Cash Flow | G54: =SUM(G49:G53) -> 103 | H54: =SUM(H49:H53) -> 109.8 | I54: =SUM(I49:I53) -> 102.5
B57: Investing Activities
C58: CAPEX | G58: -121.1 | H58: -159.7 | I58: -151.2
C59: Asset Dispositions | G59: 23.4 | H59: 13.8 | I59: 5.8
C60: Other | G60: 2.5 | H60: 2.6 | I60: 0.8
C61: Investing Cash Flow | G61: =SUM(G58:G60) -> -95.2 | H61: =SUM(H58:H60) -> -143.3 | I61: =SUM(I58:I60) -> -144.6
...

Sheet Summary
B2: =Cover!B4 -> Xcel Stores & Properties
C3: Executive Summary | I3: =IF(BalCheck=0,"Bal check: OK","ERROR") -> Bal check: OK | K3: {="Scenario: "&INDEX(S_List,S_Scenario)} -> Scenario: Base Case
I4: Actual | J4: Actual | K4: Actual | L4: Forecast | M4: Forecast | N4: Forecast | O4: Forecast | P4: Forecast
E5: units | F5: Inputs/drivers | I5: =Historical!G7 -> 2020 | J5: =I5+1 -> 2021 | K5: =J5+1 -> 2022 | L5: =K5+1 -> 2023 | M5: =L5+1 -> 2024 | N5: =M5+1 -> 2025 | O5: =N5+1 -> 2026 | P5: =O5+1 -> 2027 | R5: 2
B7: Analysis Based on: Base Case Scenario
C9: Revenue
D10: Net Revenue | E10: $MM | I10: 234.1 | J10: 258.7 | K10: 278.9 | L10: 304.2883 | M10: 330.94888 | N10: 358.93525 | O10: 388.30293 | P10: 419.10964
D11: Growth Rate | E11: % | I11: 0 | J11: 0.1050833 | K11: 0.078082721 | L11: 0.091030111 | M11: 0.087616205 | N11: 0.084564 | O11: 0.081818906 | P11: 0.079336791
C13: EBITDA
D14: EBITDA | E14: $MM | I14: 145 | J14: 150.8 | K14: 158.5 | L14: 124.14137 | M14: 138.42947 | N14: 153.46312 | O14: 169.27421 | P14: 185.89585
D15: EBITDA Margin | E15: % | I15: 0.61939342 | J15: 0.58291457 | K15: 0.56830405 | L15: 0.40797287 | M15: 0.41828051 | N15: 0.427551 | O15: 0.43593338 | P15: 0.44354944
D16: EBITDA growth rate | E16: % | I16: 0 | J16: 0.04 | K16: 0.051061008 | L16: -0.21677369 | M16: 0.11509537 | N16: 0.10860155 | O16: 0.10302858 | P16: 0.098193554
C18: Net Income
D19: Net Income | E19: $MM | I19: 48.1 | J19: 45.5 | K19: 43.1 | L19: 13.836906 | M19: 19.511661 | N19: 21.802243 | O19: 23.241398 | P19: 26.280825
D20: Net Income Margin | E20: % | I20: 0.20546775 | J20: 0.1758794 | K20: 0.15453568 | L20: 0.045473014 | M20: 0.058956722 | N20: 0.060741438 | O20: 0.059853779 | P20: 0.062706325
D21: Net Income Growth rate | E21: % | I21: 0 | J21: -0.054054054 | K21: -0.052747253 | L21: -0.67895809 | M21: 0.41011734 | N21: 0.11739551 | O21: 0.066009497 | P21: 0.13077646
C23: Dupont Analysis
D24: Return on Equity | E24: % | I24: 0.026125686 | J24: 0.024274434 | K24: 0.022659166 | L24: 0.0072709825 | M24: 0.0079331956 | N24: 0.009039658 | O24: 0.0096955982 | P24: 0.01112844
D25: Net Profit Margin | E25: % | I25: 0.20546775 | J25: 0.1758794 | K25: 0.15453568 | L25: 0.045473014 | M25: 0.058956722 | N25: 0.060741438 | O25: 0.059853779 | P25: 0.062706325
D26: Asset Turnover | E26: Multiple | I26: 0.089157177 | J26: 0.094967145 | K26: 0.099182077 | L26: 0.11281301 | M26: 0.11950493 | N26: 0.12637758 | O26: 0.13388275 | P26: 0.14202352
D27: Financial Leverage | E27: Multiple | I27: 1.4261583 | J27: 1.4533184 | K27: 1.478366 | L27: 1.4173599 | M27: 1.4163317 | N27: 1.442193 | O27: 1.4614503 | P27: 1.4739081
B30: Analysis Based on: Best Case Scenario
C32: Revenue
D33: Net Revenue | E33: $MM | I33: 234.1 | J33: 258.7 | K33: 278.9 | L33: 309.70698 | M33: 339.4467 | N33: 370.6941 | O33: 403.51293 | P33: 437.96938
D34: Growth Rate | E34: % | I34: 0 | J34: 0.1050833 | K34: 0.078082721 | L34: 0.11045887 | M34: 0.096025338 | N34: 0.092053935 | O34: 0.088533449 | P34: 0.085391204
C36: EBITDA
D37: EBITDA | E37: $MM | I37: 145 | J37: 150.8 | K37: 158.5 | L37: 129.94976 | M37: 148.12199 | N37: 167.41111 | O37: 187.86985 | P37: 209.55313
D38: EBITDA Margin | E38: % | I38: 0.61939342 | J38: 0.58291457 | K38: 0.56830405 | L38: 0.41958937 | M38: 0.43636303 | N38: 0.45161525 | O38: 0.46558571 | P38: 0.47846526
D39: EBITDA growth rate | E39: % | I39: 0 | J39: 0.04 | K39: 0.051061008 | L39: -0.18012771 | M39: 0.13984044 | N39: 0.13022456 | O39: 0.1222066 | P39: 0.1154165
C41: Net Income
D42: Net Income | E42: $MM | I42: 48.1 | J42: 45.5 | K42: 43.1 | L42: 17.757568 | M42: 26.152332 | N42: 31.497753 | O42: 36.343915 | P42: 43.167674
D43: Net Income Margin | E43: % | I43: 0.20546775 | J43: 0.1758794 | K43: 0.15453568 | L43: 0.057336672 | M43: 0.077044002 | N43: 0.084969662 | O43: 0.090068774 | P43: 0.098563223
D44: Net Income Growth rate | E44: % | I44: 0 | J44: -0.054054054 | K44: -0.052747253 | L44: -0.58799147 | M44: 0.47274293 | N44: 0.20439556 | O44: 0.1538574 | P44: 0.18775521
C46: Dupont Analysis
D47: Return on Equity | E47: % | I47: 0.026125686 | J47: 0.024274434 | K47: 0.022659166 | L47: 0.0093160391 | M47: 0.011281324 | N47: 0.013850316 | O47: 0.016084268 | P47: 0.01918248
D48: Net Profit Margin | E48: % | I48: 0.20546775 | J48: 0.1758794 | K48: 0.15453568 | L48: 0.057336672 | M48: 0.077044002 | N48: 0.084969662 | O48: 0.090068774 | P48: 0.098563223
D49: Asset Turnover | E49: Multiple | I49: 0.089157177 | J49: 0.094967145 | K49: 0.099182077 | L49: 0.11480733 | M49: 0.1225503 | N49: 0.13048509 | O49: 0.13908376 | P49: 0.14835936
D50: Financial Leverage | E50: Multiple | I50: 1.4261583 | J50: 1.4533184 | K50: 1.478366 | L50: 1.4152371 | M50: 1.4105803 | N50: 1.4309263 | O50: 1.4427456 | P50: 1.4457919
B52: Analysis Based on: Worst Case Scenario
C54: Revenue
...

Sheet Assumptions
B2: =Cover!B4 -> Xcel Stores & Properties
C3: Assumptions | I3: =IF(BalCheck=0,"Bal check: OK","ERROR") -> Bal check: OK | K3: {="Scenario: "&INDEX(S_List,S_Scenario)} -> Scenario: Base Case
I4: Actual | J4: Actual | K4: Actual | L4: Forecast | M4: Forecast | N4: Forecast | O4: Forecast | P4: Forecast
E5: units | F5: Inputs/drivers | I5: =Historical!G7 -> 2020 | J5: =I5+1 -> 2021 | K5: =J5+1 -> 2022 | L5: =K5+1 -> 2023 | M5: =L5+1 -> 2024 | N5: =M5+1 -> 2025 | O5: =N5+1 -> 2026 | P5: =O5+1 -> 2027
B7: General Assumptions
D8: Days in the period | E8: Days | I8: =DATE(I5,12,31)-DATE(I5,1,1)+1 -> 366 | J8: =DATE(J5,12,31)-DATE(J5,1,1)+1 -> 365 | K8: =DATE(K5,12,31)-DATE(K5,1,1)+1 -> 365 | L8: =DATE(L5,12,31)-DATE(L5,1,1)+1 -> 365 | M8: =DATE(M5,12,31)-DATE(M5,1,1)+1 -> 366 | N8: =DATE(N5,12,31)-DATE(N5,1,1)+1 -> 365 | O8: =DATE(O5,12,31)-DATE(O5,1,1)+1 -> 365 | P8: =DATE(P5,12,31)-DATE(P5,1,1)+1 -> 365
D9: Million | E9: Constant | F9: 1000000
B11: Styles
D12: Normal Style | E12: Number | F12: 123456
D13: Input Style | E13: Number | F13: 123456
D14: Percent Style | E14: Percent | F14: 0.12
D15: Linked Cell Style | E15: Number | F15: 123
D16: Heading | E16: Text | F16: Heading
D17: Explanatory | E17: Text | F17: Text
D18: Multiple | E18: Number | F18: 12
B20: Revenue Assumption
C22: Sales Volume
D23: Total Numbers of Properties | E23: unit | K23: 390
D24: Current Leasable Areas | E24: Square feet | K24: 1560000
D25: Land currently Built up | E25: % | K25: 0.6
D26: Land available for new property | E26: % | K26: 0.2
D28: Additional Properties Assumption | E28: unit | L28: =Scenario!L34 -> 30 | M28: =Scenario!M34 -> 30 | N28: =Scenario!N34 -> 30 | O28: =Scenario!O34 -> 30 | P28: =Scenario!P34 -> 30
C30: Sales Price
D31: Rent growth | E31: % | L31: =Scenario!L26 -> 0.03 | M31: =Scenario!M26 -> 0.03 | N31: =Scenario!N26 -> 0.03 | O31: =Scenario!O26 -> 0.03 | P31: =Scenario!P26 -> 0.03
D33: Auxilliary Income | E33: $'MM | K33: 20
D34: Inflation | E34: % | L34: =Scenario!L18 -> 0.03 | M34: =Scenario!M18 -> 0.03 | N34: =Scenario!N18 -> 0.03 | O34: =Scenario!O18 -> 0.03 | P34: =Scenario!P18 -> 0.03
B36: Operating Cost Assumption
C37: Cost of Sales [%]
D38: Variable Cost | E38: % | K38: 0.6
D39: Fixed Cost | E39: % | K39: =1-K38 -> 0.4
D40: Total | E40: % | K40: =SUM(K38:K39) -> 1
D42: Selling, General & Administrative Expenses | E42: $'MM | L42: 25
B44: CAPEX & Depreciation Assumption
D46: CAPEX Addition | E46: $'MM | L46: 140 | M46: 140 | N46: 150 | O46: 150 | P46: 150
D47: Depreciation Method | E47: Declining Balance Method
C49: Useful Life
D50: Existing Assets | E50: Years | F50: 0.02
D51: New Assets | E51: Years | F51: 0.1
B54: Working Capital Assumption
D56: =D8 -> Days in the period | E56: =E8 -> Days | I56: =I8 -> 366 | J56: =J8 -> 365 | K56: =K8 -> 365 | L56: =L8 -> 365 | M56: =M8 -> 366 | N56: =N8 -> 365 | O56: =O8 -> 365 | P56: =P8 -> 365
...

Sheet Scenario
B2: =Cover!B4 -> Xcel Stores & Properties
C3: Scenario Analysis | I3: =IF(BalCheck=0,"Bal check: OK","ERROR") -> Bal check: OK | K3: {="Scenario: "&INDEX(S_List,S_Scenario)} -> Scenario: Base Case
I4: Actual | J4: Actual | K4: Actual | L4: Forecast | M4: Forecast | N4: Forecast | O4: Forecast | P4: Forecast
E5: units | F5: Inputs/drivers | I5: =Historical!G7 -> 2020 | J5: =I5+1 -> 2021 | K5: =J5+1 -> 2022 | L5: =K5+1 -> 2023 | M5: =L5+1 -> 2024 | N5: =M5+1 -> 2025 | O5: =N5+1 -> 2026 | P5: =O5+1 -> 2027
B7: {="Scenario Analysis "&INDEX(S_List,S_Scenario)} -> Scenario Analysis Base Case
D9: Scenario Switch>>>> | F9: 1
C11: Scenario List
D12: Base Case
D13: Best Case
D14: Worst Case
B16: Inflation Scenario
D18: Used in the Model | L18: {=INDEX(L20:L22,S_Scenario)} -> 0.03 | M18: {=INDEX(M20:M22,S_Scenario)} -> 0.03 | N18: {=INDEX(N20:N22,S_Scenario)} -> 0.03 | O18: {=INDEX(O20:O22,S_Scenario)} -> 0.03 | P18: {=INDEX(P20:P22,S_Scenario)} -> 0.03
D20: Base Case | E20: % | L20: 0.03 | M20: 0.03 | N20: 0.03 | O20: 0.03 | P20: 0.03
D21: Best Case | E21: % | L21: 0.02 | M21: 0.02 | N21: 0.02 | O21: 0.02 | P21: 0.02
D22: Worst Case | E22: % | L22: 0.04 | M22: 0.04 | N22: 0.04 | O22: 0.04 | P22: 0.04
B24: Rent Growth Scenario
D26: Used in the Model | L26: {=INDEX(L28:L30,S_Scenario)} -> 0.03 | M26: {=INDEX(M28:M30,S_Scenario)} -> 0.03 | N26: {=INDEX(N28:N30,S_Scenario)} -> 0.03 | O26: {=INDEX(O28:O30,S_Scenario)} -> 0.03 | P26: {=INDEX(P28:P30,S_Scenario)} -> 0.03
D28: Base Case | E28: % | L28: 0.03 | M28: 0.03 | N28: 0.03 | O28: 0.03 | P28: 0.03
D29: Best Case | E29: % | L29: 0.04 | M29: 0.04 | N29: 0.04 | O29: 0.04 | P29: 0.04
D30: Worst Case | E30: % | L30: 0.02 | M30: 0.04 | N30: 0.04 | O30: 0.04 | P30: 0.04
B32: Additional Properties Scenario
D34: Used in the Model | L34: {=INDEX(L36:L38,S_Scenario)} -> 30 | M34: {=INDEX(M36:M38,S_Scenario)} -> 30 | N34: {=INDEX(N36:N38,S_Scenario)} -> 30 | O34: {=INDEX(O36:O38,S_Scenario)} -> 30 | P34: {=INDEX(P36:P38,S_Scenario)} -> 30
D36: Base Case | E36: units | L36: 30 | M36: 30 | N36: 30 | O36: 30 | P36: 30
D37: Best Case | E37: units | L37: 35 | M37: 35 | N37: 35 | O37: 35 | P37: 35
D38: Worst Case | E38: units | L38: 25 | M38: 25 | N38: 25 | O38: 25 | P38: 25

Sheet Model
B2: =Cover!B4 -> Xcel Stores & Properties
C3: Model | I3: =IF(BalCheck=0,"Bal check: OK","ERROR") -> Bal check: OK | K3: {="Scenario: "&INDEX(S_List,S_Scenario)} -> Scenario: Base Case
I4: Actual | J4: Actual | K4: Actual | L4: Forecast | M4: Forecast | N4: Forecast | O4: Forecast | P4: Forecast
E5: units | F5: Inputs/drivers | I5: =Historical!G7 -> 2020 | J5: =I5+1 -> 2021 | K5: =J5+1 -> 2022 | L5: =K5+1 -> 2023 | M5: =L5+1 -> 2024 | N5: =M5+1 -> 2025 | O5: =N5+1 -> 2026 | P5: =O5+1 -> 2027 | R5: 2
B7: Financial Statements
C9: Income Statements
D11: =Historical!C13 -> Revenue | E11: $'MM | I11: =Historical!G13 -> 234.1 | J11: =Historical!H13 -> 258.7 | K11: =Historical!I13 -> 278.9 | L11: =L155 -> 307.77985 | M11: =M155 -> 338.14147 | N11: =N155 -> 370.0478 | O11: =O155 -> 403.56417 | P11: =P155 -> 423.36689 | R11: =IF($R$5=1,_xlfn.FORMULATEXT(P11),"")
D13: =Historical!C15 -> Operating Costs | E13: $'MM | I13: =Historical!G15 -> 74.6 | J13: =Historical!H15 -> 91.8 | K13: =Historical!I15 -> 102.9 | L13: =L175 -> 110.87871 | M13: =M175 -> 119.24353 | N13: =N175 -> 128.01045 | O13: =O175 -> 137.19606 | P13: =P175 -> 143.14716 | R13: =IF($R$5=1,_xlfn.FORMULATEXT(P13),"")
D14: =Historical!C16 -> SG&A | E14: $'MM | I14: =Historical!G16 -> 14.5 | J14: =Historical!H16 -> 16.9 | K14: =Historical!I16 -> 19.8 | L14: =L177 -> 25 | M14: =M177 -> 25.75 | N14: =N177 -> 26.5225 | O14: =O177 -> 27.318175 | P14: =P177 -> 28.13772 | R14: =IF($R$5=1,_xlfn.FORMULATEXT(P14),"")
D15: =Historical!C17 -> Total Costs | E15: $'MM | I15: =I13+I14 -> 89.1 | J15: =J13+J14 -> 108.7 | K15: =K13+K14 -> 122.7 | L15: =L13+L14 -> 135.87871 | M15: =M13+M14 -> 144.99353 | N15: =N13+N14 -> 154.53295 | O15: =O13+O14 -> 164.51424 | P15: =P13+P14 -> 171.28488 | R15: =IF($R$5=1,_xlfn.FORMULATEXT(P15),"")
D17: =Historical!C19 -> Cost Adjustments - Gain / (Loss) | E17: $'MM | I17: =Historical!G19 -> 0 | J17: =Historical!H19 -> 0.8 | K17: =Historical!I19 -> 2.3 | L17: =Assumptions!L114 -> 0 | M17: =Assumptions!M114 -> 0 | N17: =Assumptions!N114 -> 0 | O17: =Assumptions!O114 -> 0 | P17: =Assumptions!P114 -> 0 | R17: =IF($R$5=1,_xlfn.FORMULATEXT(P17),"")
D18: =Historical!C20 -> EBITDA | E18: $'MM | I18: =I11-I15+I17 -> 145 | J18: =J11-J15+J17 -> 150.8 | K18: =K11-K15+K17 -> 158.5 | L18: =L11-L15+L17 -> 171.90114 | M18: =M11-M15+M17 -> 193.14795 | N18: =N11-N15+N17 -> 215.51485 | O18: =O11-O15+O17 -> 239.04993 | P18: =P11-P15+P17 -> 252.08201 | R18: =IF($R$5=1,_xlfn.FORMULATEXT(P18),"")
D20: =Historical!C22 -> Depreciation | E20: $'MM | I20: =Historical!G22 -> 41.7 | J20: =Historical!H22 -> 46.2 | K20: =Historical!I22 -> 54.6 | L20: =L246 -> 57.844 | M20: =M246 -> 70.12712 | N20: =N246 -> 81.600578 | O20: =O246 -> 92.346966 | P20: =P246 -> 101.94059 | R20: =IF($R$5=1,_xlfn.FORMULATEXT(P20),"")
D21: =Historical!C23 -> EBIT | E21: $'MM | I21: =I18-I20 -> 103.3 | J21: =J18-J20 -> 104.6 | K21: =K18-K20 -> 103.9 | L21: =L18-L20 -> 114.05714 | M21: =M18-M20 -> 123.02083 | N21: =N18-N20 -> 133.91427 | O21: =O18-O20 -> 146.70297 | P21: =P18-P20 -> 150.14142 | R21: =IF($R$5=1,_xlfn.FORMULATEXT(P21),"")
D23: =Historical!C25 -> Foreign Exchange - Gain / (Loss) | E23: $'MM | I23: =Historical!G25 -> 0 | J23: =Historical!H25 -> -2.6 | K23: =Historical!I25 -> 0 | L23: =Assumptions!L115 -> 0 | M23: =Assumptions!M115 -> 0 | N23: =Assumptions!N115 -> 0 | O23: =Assumptions!O115 -> 0 | P23: =Assumptions!P115 -> 0 | R23: =IF($R$5=1,_xlfn.FORMULATEXT(P23),"")
D24: =Historical!C26 -> Net Interest Expense | E24: $'MM | I24: =Historical!G26 -> 33.5 | J24: =Historical!H26 -> 34.2 | K24: =Historical!I26 -> 36.6 | L24: =L383 -> 45.79825 | M24: =M383 -> 39.08114 | N24: =N383 -> 25.73465 | O24: =O383 -> 14.232319 | P24: =P383 -> 5.552419 | R24: =IF($R$5=1,_xlfn.FORMULATEXT(P24),"")
D25: =Historical!C27 -> EBT | E25: $'MM | I25: =I21+I23-I24 -> 69.8 | J25: =J21+J23-J24 -> 67.8 | K25: =K21+K23-K24 -> 67.3 | L25: =L21+L23-L24 -> 68.258888 | M25: =M21+M23-M24 -> 83.939686 | N25: =N21+N23-N24 -> 108.17962 | O25: =O21+O23-O24 -> 132.47065 | P25: =P21+P23-P24 -> 144.589 | R25: =IF($R$5=1,_xlfn.FORMULATEXT(P25),"")
D27: =Historical!C29 -> Current Taxes | E27: $'MM | I27: =Historical!G29 -> 11.3 | J27: =Historical!H29 -> 10.5 | K27: =Historical!I29 -> 15.8 | L27: =L294 -> 20.559139 | M27: =M294 -> 25.655398 | N27: =N294 -> 33.533377 | O27: =O294 -> 41.427961 | P27: =P294 -> 45.366426 | R27: =IF($R$5=1,_xlfn.FORMULATEXT(P27),"")
D28: =Historical!C30 -> Deferred Income Taxes | E28: $'MM | I28: =Historical!G30 -> 10.4 | J28: =Historical!H30 -> 11.8 | K28: =Historical!I30 -> 8.4 | L28: =L295 -> 1.625 | M28: =M295 -> 1.625 | N28: =N295 -> 1.625 | O28: =O295 -> 1.625 | P28: =P295 -> 1.625 | R28: =IF($R$5=1,_xlfn.FORMULATEXT(P28),"")
D29: =Historical!C31 -> Total Income Taxes | E29: $'MM | I29: =SUM(I27:I28) -> 21.7 | J29: =SUM(J27:J28) -> 22.3 | K29: =SUM(K27:K28) -> 24.2 | L29: =SUM(L27:L28) -> 22.184139 | M29: =SUM(M27:M28) -> 27.280398 | N29: =SUM(N27:N28) -> 35.158377 | O29: =SUM(O27:O28) -> 43.052961 | P29: =SUM(P27:P28) -> 46.991426 | R29: =IF($R$5=1,_xlfn.FORMULATEXT(P29),"")
D31: =Historical!C33 -> Net Income | E31: $'MM | I31: =I25-I29 -> 48.1 | J31: =J25-J29 -> 45.5 | K31: =K25-K29 -> 43.1 | L31: =L25-L29 -> 46.07475 | M31: =M25-M29 -> 56.659288 | N31: =N25-N29 -> 73.021245 | O31: =O25-O29 -> 89.417688 | P31: =P25-P29 -> 97.597577 | R31: =IF($R$5=1,_xlfn.FORMULATEXT(P31),"")
D33: =Historical!C35 -> Preferred Dividend | E33: $'MM | I33: =Historical!G35 -> 0 | J33: =Historical!H35 -> 0 | K33: =Historical!I35 -> 0 | L33: =L318 -> 0 | M33: =M318 -> 32 | N33: =N318 -> 64 | O33: =O318 -> 64 | P33: =P318 -> 64 | R33: =IF($R$5=1,_xlfn.FORMULATEXT(P33),"")
D34: =Historical!C36 -> Net Income to Common | E34: $'MM | I34: =I31-I33 -> 48.1 | J34: =J31-J33 -> 45.5 | K34: =K31-K33 -> 43.1 | L34: =L31-L33 -> 46.07475 | M34: =M31-M33 -> 24.659288 | N34: =N31-N33 -> 9.0212445 | O34: =O31-O33 -> 25.417688 | P34: =P31-P33 -> 33.597577 | R34: =IF($R$5=1,_xlfn.FORMULATEXT(P34),"")
D36: EBITDA Margin | E36: % | I36: =I18/I11 -> 0.61939342 | J36: =J18/J11 -> 0.58291457 | K36: =K18/K11 -> 0.56830405 | L36: =L18/L11 -> 0.5585198 | M36: =M18/M11 -> 0.57120454 | N36: =N18/N11 -> 0.58239733 | O36: =O18/O11 -> 0.59234677 | P36: =P18/P11 -> 0.59542211 | R36: =IF($R$5=1,_xlfn.FORMULATEXT(P36),"")
C37: Dupont Analysis
D38: Return on Equity | E38: % | I38: =I34/I111 -> 0.026125686 | J38: =J34/J111 -> 0.024274434 | K38: =K34/K111 -> 0.022659166 | L38: =L34/L111 -> 0.023891508 | M38: =M34/M111 -> 0.010547263 | N38: =N34/N111 -> 0.0032863002 | O38: =O34/O111 -> 0.0091920335 | P38: =P34/P111 -> 0.012034685 | R38: =IF($R$5=1,_xlfn.FORMULATEXT(P38),"")
D39: Net Profit Margin | E39: % | I39: =I31/I11 -> 0.20546775 | J39: =J31/J11 -> 0.1758794 | K39: =K31/K11 -> 0.15453568 | L39: =L31/L11 -> 0.14970035 | M39: =M31/M11 -> 0.16756089 | N39: =N31/N11 -> 0.19732922 | O39: =O31/O11 -> 0.22156994 | P39: =P31/P11 -> 0.23052718 | R39: =IF($R$5=1,_xlfn.FORMULATEXT(P39),"")
D40: Asset Turnover | E40: Multiple | I40: =I11/I90 -> 0.089157177 | J40: =J11/J90 -> 0.094967145 | K40: =K11/K90 -> 0.099182077 | L40: =L11/L90 -> 0.11417627 | M40: =M11/M90 -> 0.11719452 | N40: =N11/N90 -> 0.11892624 | O40: =O11/O90 -> 0.13676314 | P40: =P11/P90 -> 0.14357879 | R40: =IF($R$5=1,_xlfn.FORMULATEXT(P40),"")
D41: Financial Leverage | E41: Multiple | I41: =I90/I111 -> 1.4261583 | J41: =J90/J111 -> 1.4533184 | K41: =K90/K111 -> 1.478366 | L41: =L90/L111 -> 1.3977996 | M41: =M90/M111 -> 1.2341 | N41: =N90/N111 -> 1.1334984 | O41: =O90/O111 -> 1.0671344 | P41: =P90/P111 -> 1.0562176 | R41: =IF($R$5=1,_xlfn.FORMULATEXT(P41),"")
C44: Cashflow Statements
C46: =Historical!B48 -> Operating Activities
D47: =Historical!C49 -> Net Income | E47: $'MM | I47: =I31 -> 48.1 | J47: =J31 -> 45.5 | K47: =K31 -> 43.1 | L47: =L31 -> 46.07475 | M47: =M31 -> 56.659288 | N47: =N31 -> 73.021245 | O47: =O31 -> 89.417688 | P47: =P31 -> 97.597577 | R47: =IF($R$5=1,_xlfn.FORMULATEXT(P47),"")
D48: =Historical!C50 -> Depreciation | E48: $'MM | I48: =Historical!G50 -> 41.7 | J48: =Historical!H50 -> 46.2 | K48: =Historical!I50 -> 54.6 | L48: =L20 -> 57.844 | M48: =M20 -> 70.12712 | N48: =N20 -> 81.600578 | O48: =O20 -> 92.346966 | P48: =P20 -> 101.94059 | R48: =IF($R$5=1,_xlfn.FORMULATEXT(P48),"")
D49: =Historical!C51 -> Deferred Income Taxes | E49: $'MM | I49: =Historical!G51 -> 10.4 | J49: =Historical!H51 -> 11.8 | K49: =Historical!I51 -> 8.4 | L49: =L28 -> 1.625 | M49: =M28 -> 1.625 | N49: =N28 -> 1.625 | O49: =O28 -> 1.625 | P49: =P28 -> 1.625 | R49: =IF($R$5=1,_xlfn.FORMULATEXT(P49),"")
D50: =Historical!C52 -> Changes in Working Capital | E50: $'MM | I50: =Historical!G52 -> 2.4 | J50: =Historical!H52 -> 6.7 | K50: =Historical!I52 -> -3.3 | L50: =L280 -> 1.4430437 | M50: =M280 -> -0.064093152 | N50: =N280 -> -0.041530801 | O50: =O280 -> -0.065259344 | P50: =P280 -> 0.08472368 | R50: =IF($R$5=1,_xlfn.FORMULATEXT(P50),"")
D51: =Historical!C53 -> Other | E51: $'MM | I51: =Historical!G53 -> 0.4 | J51: =Historical!H53 -> -0.4 | K51: =Historical!I53 -> -0.3 | L51: =Assumptions!L116 -> 0 | M51: =Assumptions!M116 -> 0 | N51: =Assumptions!N116 -> 0 | O51: =Assumptions!O116 -> 0 | P51: =Assumptions!P116 -> 0 | R51: =IF($R$5=1,_xlfn.FORMULATEXT(P51),"")
D52: =Historical!C54 -> Operating Cash Flow | E52: $'MM | I52: =SUM(I47:I51) -> 103 | J52: =SUM(J47:J51) -> 109.8 | K52: =SUM(K47:K51) -> 102.5 | L52: =SUM(L47:L51) -> 106.98679 | M52: =SUM(M47:M51) -> 128.34731 | N52: =SUM(N47:N51) -> 156.20529 | O52: =SUM(O47:O51) -> 183.3244 | P52: =SUM(P47:P51) -> 201.24789 | R52: =IF($R$5=1,_xlfn.FORMULATEXT(P52),"")
C54: =Historical!B57 -> Investing Activities
D55: =Historical!C58 -> CAPEX | E55: $'MM | I55: =Historical!G58 -> -121.1 | J55: =Historical!H58 -> -159.7 | K55: =Historical!I58 -> -151.2 | L55: =-L245 -> -140 | M55: =-M245 -> -140 | N55: =-N245 -> -150 | O55: =-O245 -> -150 | P55: =-P245 -> -150 | R55: =IF($R$5=1,_xlfn.FORMULATEXT(P55),"")
D56: =Historical!C59 -> Asset Dispositions | E56: $'MM | I56: =Historical!G59 -> 23.4 | J56: =Historical!H59 -> 13.8 | K56: =Historical!I59 -> 5.8 | L56: =Assumptions!L118 -> 0 | M56: =Assumptions!M118 -> 0 | N56: =Assumptions!N118 -> 0 | O56: =Assumptions!O118 -> 0 | P56: =Assumptions!P118 -> 0 | R56: =IF($R$5=1,_xlfn.FORMULATEXT(P56),"")
...

Sheet Template
B2: =Cover!B4 -> Xcel Stores & Properties
C3: Sheet Name | I3: =IF(BalCheck=0,"Bal check: OK","ERROR") -> Bal check: OK | K3: {="Scenario: "&INDEX(S_List,S_Scenario)} -> Scenario: Base Case
I4: Actual | J4: Actual | K4: Actual | L4: Forecast | M4: Forecast | N4: Forecast | O4: Forecast | P4: Forecast
E5: units | F5: Inputs/drivers | I5: =Historical!G7 -> 2020 | J5: =I5+1 -> 2021 | K5: =J5+1 -> 2022 | L5: =K5+1 -> 2023 | M5: =L5+1 -> 2024 | N5: =M5+1 -> 2025 | O5: =N5+1 -> 2026 | P5: =O5+1 -> 2027
